using Microsoft.AspNetCore.Mvc;
using PruebaTostao.Exceptions;

namespace PruebaTostao.Middleware; 

public class ExceptionHandlingMiddleware
{
    private readonly RequestDelegate _next;
    private readonly ILogger<ExceptionHandlingMiddleware> _logger;

    public ExceptionHandlingMiddleware(RequestDelegate next, ILogger<ExceptionHandlingMiddleware> logger)
    {
        _next = next;
        _logger = logger;
    }

    public async Task InvokeAsync(HttpContext context)
    {
        try
        {
            await _next(context);
        }
        catch (Exception exception)
        {
            _logger.LogError(exception, "Ocurrió una excepción: {Message}", exception.Message);

            var exceptionDetails = GetExceptionDetails(exception);

            var problemDetails = new ProblemDetails
            {
                Status = exceptionDetails.Status,
                Type = exceptionDetails.Type,
                Title = exceptionDetails.Title,
                Detail = exceptionDetails.Detail
            };

            if (exceptionDetails.Errors is not null)
            {
                problemDetails.Extensions["errors"] = exceptionDetails.Errors;
            }

            context.Response.StatusCode = exceptionDetails.Status;
            await context.Response.WriteAsJsonAsync(problemDetails);
        }
    }

    private static ExceptionDetails GetExceptionDetails(Exception exception)
    {
        return exception switch
        {
            ValidationException validationException => new ExceptionDetails(
                StatusCodes.Status400BadRequest,
                "ValidationFailure",
                "Error de Validación",
                "Han ocurrido uno o más errores de validación.",
                validationException.Errors
            ),
            _ => new ExceptionDetails(
                StatusCodes.Status500InternalServerError,
                "ServerError",
                "Error del Servidor",
                "Ocurrió un error interno inesperado en el servidor.",
                null
            )
        };
    }

    internal record ExceptionDetails(
        int Status,
        string Type,
        string Title,
        string Detail,
        IEnumerable<object>? Errors
    );
}